Workbook
Name Comments: '[1]DISPATCH SHEET'!#REF!
Name LateComment: '[1]DISPATCH SHEET'!#REF!
Name LateComments: #REF!

Sheet Inputs
A1: Day of the Week | E1: Attendance Sheet 1st Shift | H1: Monday | J1: Monday | K1: 1 | L1: Total Available | M1: =COUNTIF(G3:G52, "x") + COUNTIF(P3:P52, "x") -> 0
A2: Shift | E2: Name | F2: Shift | G2: Present | H2: Tuesday | J2: Tuesday | K2: 2
A3: Total Cases | E3: Alex G. | F3: 1 | H3: Wednesday | J3: Wednesday
A4: Hours Remaining | B4: 9.5 | E4: Andrew Bartell | F4: 2 | H4: Thursday
A5: Cases to Pick | B5: =IF(B2="1st", IF(B1="Sunday",B3*0.2, IF(B1="Monday",B3*0.18, IF(B1="Tuesday",B3*0.18, IF(B1="Wednesday",B3*0.19, IF(B1="Thursday",B3*0.19, IF(B1="Friday",B3*0.18, IF(B1="Saturday",B3*0.21,0))))))), IF(B2="2nd", IF(B1="Sunday",B3*0.19, IF(B1="Monday",B3*0.15, IF(B1="Tuesday",B3*0.15, IF(B1="Wednesday",B3*0.17, IF(B1="Thursday",B3*0.17, IF(B1="Friday",B3*0.17, IF(B1="Saturday",B3*0.19,0))))))), 0)) -> 0 | E5: Anthony L | F5: 1 | H5: Friday | J5: Thursday
A6: Full Pallets | B6: =IF(AND(B1="Sunday",B2="1st"),B3*0.28, IF(AND(B1="Monday",B2="1st"),B3*0.32, IF(AND(B1="Tuesday",B2="1st"),B3*0.4, IF(AND(B1="Wednesday",B2="1st"),B3*0.35, IF(AND(B1="Thursday",B2="1st"),B3*0.35, IF(AND(B1="Friday",B2="1st"),B3*0.36, IF(AND(B1="Saturday",B2="1st"),B3*0.31, IF(AND(B1="Sunday",B2="2nd"),B3*0.32, IF(AND(B1="Monday",B2="2nd"),B3*0.33, IF(AND(B1="Tuesday",B2="2nd"),B3*0.27, IF(AND(B1="Wednesday",B2="2nd"),B3*0.29, IF(AND(B1="Thursday",B2="2nd"),B3*0.28, IF(AND(B1="Friday",B2="2nd"),B3*0.3, IF(AND(B1="Saturday",B2="2nd"),B3*0.3,0))))))))))))))/70 -> 0 | E6: Anthony T | F6: 1 | H6: Saturday | J6: Friday
A7: Total Outbound Loads | B7: =(B3/70) / 25 *0.52 -> 0 | E7: Antonio D. | F7: 1 | H7: Sunday | J7: Saturday
A8: Crossroads Running | E8: Ariel | F8: 1 | J8: Sunday
A9: Deer Creek Running | E9: Ashton Sudduth | F9: 2
A10: MSB Running | E10: Billy Anderson | F10: 2
E11: Bressa Gonzaga | F11: 2
E12: Brett W. | F12: 1
A13: Info*** | E13: Brian B. | F13: 1
A14: 1st Shift = 9.5h | E14: Brian Manis | F14: 2
A15: 2nd Shift = 11h | E15: Bryce Andrews | F15: 2
E16: Carlos | F16: 1
E17: Charles Myers | F17: 2
E18: Chaz Lacey | F18: 2
E19: Chris Dodds | F19: 2
E20: Cristopher R. | F20: 1
E21: Dale Ferguson | F21: 1
E22: Dale Hrenchir | F22: 1
E23: Daniel V. | F23: 1
E24: Danny Trotter | F24: 2
E25: Daryl M | F25: 1
E26: Dashawn B. | F26: 1
E27: David Norwood | F27: 2
... E98: Will Perkins. | F98: 1

Sheet Crew Sheet
A1: Name | B1: Shift | C1: Present | D1: Recommended Task | E1: Today's Task | F1: Yes | H1: Total Pickers: | I1: =I12 -> 0 | J1: Monday | M1: 1st | T1: Unloading | W1: Picking
A2: Alex G. | B2: 1 | C2: =Inputs!G3 -> 0 | E2: =Table200[[#This Row],[Recommended Task]] -> 0 | F2: No | H2: Total Taskers: | I2: =COUNTIF(E2:E48,"*Tasking*")+COUNTIF(E2:E48,"*Replenishment*")+COUNTIF(E2:E48,"*Putaways*")+COUNTIF(E2:E48,"* Full Pallet*") -> 0 | J2: Tuesday | M2: 2nd | T2: Loading | W2: Replenishment
A3: Andrew Bartell | B3: 2 | C3: =Inputs!G4 -> 0 | D3: =IF($C3<>"x","",IFERROR(_xlfn.XLOOKUP($A3,'Staffing Sheet 2nd Shift'!$A:$A,'Staffing Sheet 2nd Shift'!$I:$I,""),"")) | E3: =Table200[[#This Row],[Recommended Task]] | H3: Total Receivers: | I3: =I10 -> 0 | T3: Receiving | W3: Full Pallets
A4: Anthony L | B4: 1 | C4: =Inputs!G5 -> 0 | H4: Total Unloaders: | I4: =I9 -> 0 | J4: Wednesday | T4: Picking | W4: Receiving
A5: Anthony T | B5: 1 | C5: =Inputs!G6 -> 0 | D5: =IF($C5<>"x","",IFERROR(_xlfn.XLOOKUP($A5,'Staffing sheet 1ST Shift'!$A:$A,'Staffing sheet 1ST Shift'!$I:$I,""),"")) | E5: =Table200[[#This Row],[Recommended Task]] | H5: Total Loaders: | I5: =I15 -> 0 | J5: Thursday | T5: Full Pallet Puller | W5: Putaways
A6: Antonio D. | B6: 1 | C6: =Inputs!G7 -> 0 | D6: =IF($C6<>"x","",IFERROR(_xlfn.XLOOKUP($A6,'Staffing sheet 1ST Shift'!$A:$A,'Staffing sheet 1ST Shift'!$I:$I,""),"")) | E6: =Table200[[#This Row],[Recommended Task]] | J6: Friday | T6: Replenishment | W6: Unloading
A7: Ariel | B7: 1 | C7: =Inputs!G8 -> 0 | D7: =IF($C7<>"x","",IFERROR(_xlfn.XLOOKUP($A7,'Staffing sheet 1ST Shift'!$A:$A,'Staffing sheet 1ST Shift'!$I:$I,""),"")) | E7: =Table200[[#This Row],[Recommended Task]] | J7: Saturday | W7: Loading
A8: Ashton Sudduth | B8: 2 | C8: =Inputs!G9 -> 0 | D8: =IF($C8<>"x","",IFERROR(_xlfn.XLOOKUP($A8,'Staffing Sheet 2nd Shift'!$A:$A,'Staffing Sheet 2nd Shift'!$I:$I,""),"")) | E8: =Table200[[#This Row],[Recommended Task]] | H8: Task | I8: Available Staff | J8: Column1 | K8: Inbound/Outbound | L8: Needed | N8: Workers Gap | O8: Hours Gap | P8: Status | Q8: Expected Volume | R8: Expected Completed Cases | S8: Completion % | T8: Priority | U8: Recommendation | W8: Extra
A9: Billy Anderson | B9: 2 | C9: =Inputs!G10 -> 0 | D9: =IF($C9<>"x","",IFERROR(_xlfn.XLOOKUP($A9,'Staffing Sheet 2nd Shift'!$A:$A,'Staffing Sheet 2nd Shift'!$I:$I,""),"")) | E9: =Table200[[#This Row],[Recommended Task]] | H9: Unloaders | I9: =COUNTIF(E1:E48, "Unloading") -> 0 | K9: Inbound | L9: =2 -> 2 | N9: =Table2[[#This Row],[Available Staff ]]-Table2[[#This Row],[Needed ]] -> -2 | O9: =Table5[[#This Row],[Workers Gap]]*I3 -> 0 | P9: =IF(N9<0,"Understaffed",IF(N9=0,"Good","Overstaffed")) -> Understaffed | Q9: =ROUNDUP(Q11/2,0) -> 0 | R9: =44*'Crew Sheet'!I3*Table2[[#This Row],[Available Staff ]] -> 0 | S9: =Table4[[#This Row],[Expected Completed Cases]]/Table4[[#This Row],[Expected Volume]] -> #DIV/0! | T9: =IF($H9="Picking","PROTECT - PICKING BOTTLENECK",IF($P9="Understaffed","URGENT - ADD STAFF",IF(AND($P9="Overstaffed",$S9>=100%),"AVAILABLE TO MOVE",IF(AND($P9="Overstaffed",$S9<100%),"HIGH - DO NOT PULL","OK")))) -> URGENT - ADD STAFF | U9: =IF(N9<0,"Need "&ROUND(ABS(N9),1)&" more workers / "&ROUND(ABS(O9),1)&" labor hrs",IF(N9>0,"Can move "&ROUND(N9,1)&" workers / "&ROUND(O9,1)&" labor hrs","Balanced Staffing")) -> Need 2 more workers / 0 labor hrs
A10: Bressa Gonzaga | B10: 2 | C10: =Inputs!G11 -> 0 | D10: =IF($C10<>"x","",IFERROR(_xlfn.XLOOKUP($A10,'Staffing Sheet 2nd Shift'!$A:$A,'Staffing Sheet 2nd Shift'!$I:$I,""),"")) | E10: =Table200[[#This Row],[Recommended Task]] | H10: Receivers | I10: =COUNTIF(E2:E48, "Receiving") -> 0 | K10: Inbound | L10: 2 | N10: =Table2[[#This Row],[Available Staff ]]-Table2[[#This Row],[Needed ]] -> -2 | O10: =Table5[[#This Row],[Workers Gap]]*$I$3 -> 0 | P10: =IF(N10<0,"Understaffed",IF(N10=0,"Good","Overstaffed")) -> Understaffed | Q10: =ROUNDUP(Q11/2,0) -> 0 | R10: =44*I3*Table2[[#This Row],[Available Staff ]] -> 0 | S10: =Table4[[#This Row],[Expected Completed Cases]]/Table4[[#This Row],[Expected Volume]] -> #DIV/0! | T10: =IF($H10="Picking","PROTECT - PICKING BOTTLENECK",IF($P10="Understaffed","URGENT - ADD STAFF",IF(AND($P10="Overstaffed",$S10>=100%),"AVAILABLE TO MOVE",IF(AND($P10="Overstaffed",$S10<100%),"HIGH - DO NOT PULL","OK")))) -> URGENT - ADD STAFF | U10: =IF(N10<0,"Need "&ROUND(ABS(N10),1)&" more workers / "&ROUND(ABS(O10),1)&" labor hrs",IF(N10>0,"Can move "&ROUND(N10,1)&" workers / "&ROUND(O10,1)&" labor hrs","Balanced Staffing")) -> Need 2 more workers / 0 labor hrs
A11: Brett W. | B11: 1 | C11: =Inputs!G12 -> 0 | D11: =IF($C11<>"x","",IFERROR(_xlfn.XLOOKUP($A11,'Staffing sheet 1ST Shift'!$A:$A,'Staffing sheet 1ST Shift'!$I:$I,""),"")) | E11: =Table200[[#This Row],[Recommended Task]] | H11: Putaway | I11: =COUNTIF(E2:E48, "Putaways") -> 0 | K11: Inbound | L11: =('Staffing Forecast'!AB13/2)/(25*Inputs!B4) -> 0 | N11: =Table2[[#This Row],[Available Staff ]]-Table2[[#This Row],[Needed ]] -> 0 | O11: =Table5[[#This Row],[Workers Gap]]*$I$3 -> 0 | P11: =IF(N11<0,"Understaffed",IF(N11=0,"Good","Overstaffed")) -> Good | Q11: =IF(I2="1st",'Staffing Forecast'!AB13*0.52, 'Staffing Forecast'!AB13*0.48) -> 0 | R11: =25*I3*Table2[[#This Row],[Available Staff ]] -> 0 | S11: =Table4[[#This Row],[Expected Completed Cases]]/Table4[[#This Row],[Expected Volume]] -> #DIV/0! | T11: =IF($H11="Picking","PROTECT - PICKING BOTTLENECK",IF($P11="Understaffed","URGENT - ADD STAFF",IF(AND($P11="Overstaffed",$S11>=100%),"AVAILABLE TO MOVE",IF(AND($P11="Overstaffed",$S11<100%),"HIGH - DO NOT PULL","OK")))) -> #DIV/0! | U11: =IF(N11<0,"Need "&ROUND(ABS(N11),1)&" more workers / "&ROUND(ABS(O11),1)&" labor hrs",IF(N11>0,"Can move "&ROUND(N11,1)&" workers / "&ROUND(O11,1)&" labor hrs","Balanced Staffing")) -> Balanced Staffing
A12: Brian B. | B12: 1 | C12: =Inputs!G13 -> 0 | D12: =IF($C12<>"x","",IFERROR(_xlfn.XLOOKUP($A12,'Staffing sheet 1ST Shift'!$A:$A,'Staffing sheet 1ST Shift'!$I:$I,""),"")) | E12: =Table200[[#This Row],[Recommended Task]] | H12: Picking | I12: =COUNTIF(E2:E51, "Picking") -> 0 | K12: Outbound | L12: =(Inputs!B5/(185*Inputs!B4)) -> 0 | N12: =Table2[[#This Row],[Available Staff ]]-Table2[[#This Row],[Needed ]] -> 0 | O12: =Table5[[#This Row],[Workers Gap]]*$I$3 -> 0 | P12: =IF(N12<0,"Understaffed",IF(N12=0,"Good","Overstaffed")) -> Good | Q12: =I5 -> 0 | R12: =185*'Crew Sheet'!I3*Table2[[#This Row],[Available Staff ]] -> 0 | S12: =Table4[[#This Row],[Expected Completed Cases]]/Table4[[#This Row],[Expected Volume]] -> #DIV/0! | T12: =IF($H12="Picking","PROTECT - PICKING BOTTLENECK",IF($P12="Understaffed","URGENT - ADD STAFF",IF(AND($P12="Overstaffed",$S12>=100%),"AVAILABLE TO MOVE",IF(AND($P12="Overstaffed",$S12<100%),"HIGH - DO NOT PULL","OK")))) -> #DIV/0! | U12: =IF(N12<0,"Need "&ROUND(ABS(N12),1)&" more workers / "&ROUND(ABS(O12),1)&" labor hrs",IF(N12>0,"Can move "&ROUND(N12,1)&" workers / "&ROUND(O12,1)&" labor hrs","Balanced Staffing")) -> Balanced Staffing
A13: Brian Manis | B13: 2 | C13: =Inputs!G14 -> 0 | D13: =IF($C13<>"x","",IFERROR(_xlfn.XLOOKUP($A13,'Staffing Sheet 2nd Shift'!$A:$A,'Staffing Sheet 2nd Shift'!$I:$I,""),"")) | E13: =Table200[[#This Row],[Recommended Task]] | H13: Replenishment | I13: =COUNTIF(E2:E52, "Replenishment") -> 0 | K13: Outbound | L13: =(Inputs!B5/70)/(25*8.5) -> 0 | N13: =Table2[[#This Row],[Available Staff ]]-Table2[[#This Row],[Needed ]] -> 0 | O13: =Table5[[#This Row],[Workers Gap]]*$I$3 -> 0 | P13: =IF(N13<0,"Understaffed",IF(N13=0,"Good","Overstaffed")) -> Good | Q13: =I5/70 -> 0 | R13: =25*I3*Table2[[#This Row],[Available Staff ]] -> 0 | S13: =Table4[[#This Row],[Expected Completed Cases]]/Table4[[#This Row],[Expected Volume]] -> #DIV/0! | T13: =IF($H13="Picking","PROTECT - PICKING BOTTLENECK",IF($P13="Understaffed","URGENT - ADD STAFF",IF(AND($P13="Overstaffed",$S13>=100%),"AVAILABLE TO MOVE",IF(AND($P13="Overstaffed",$S13<100%),"HIGH - DO NOT PULL","OK")))) -> #DIV/0! | U13: =IF(N13<0,"Need "&ROUND(ABS(N13),1)&" more workers / "&ROUND(ABS(O13),1)&" labor hrs",IF(N13>0,"Can move "&ROUND(N13,1)&" workers / "&ROUND(O13,1)&" labor hrs","Balanced Staffing")) -> Balanced Staffing
A14: Bryce Andrews | B14: 2 | C14: =Inputs!G15 -> 0 | D14: =IF($C14<>"x","",IFERROR(_xlfn.XLOOKUP($A14,'Staffing Sheet 2nd Shift'!$A:$A,'Staffing Sheet 2nd Shift'!$I:$I,""),"")) | E14: =Table200[[#This Row],[Recommended Task]] | H14: Full Pallet Pullers | I14: =COUNTIF(E2:E53, "Full Pallets") -> 0 | K14: Outbound | L14: =(Inputs!B6/(25*Inputs!B4)) -> 0 | N14: =Table2[[#This Row],[Available Staff ]]-Table2[[#This Row],[Needed ]] -> 0 | O14: =Table5[[#This Row],[Workers Gap]]*$I$3 -> 0 | P14: =IF(N14<0,"Understaffed",IF(N14=0,"Good","Overstaffed")) -> Good | Q14: =I6 -> 0 | R14: =25*I3*Table2[[#This Row],[Available Staff ]] -> 0 | S14: =Table4[[#This Row],[Expected Completed Cases]]/Table4[[#This Row],[Expected Volume]] -> #DIV/0! | T14: =IF($H14="Picking","PROTECT - PICKING BOTTLENECK",IF($P14="Understaffed","URGENT - ADD STAFF",IF(AND($P14="Overstaffed",$S14>=100%),"AVAILABLE TO MOVE",IF(AND($P14="Overstaffed",$S14<100%),"HIGH - DO NOT PULL","OK")))) -> #DIV/0! | U14: =IF(N14<0,"Need "&ROUND(ABS(N14),1)&" more workers / "&ROUND(ABS(O14),1)&" labor hrs",IF(N14>0,"Can move "&ROUND(N14,1)&" workers / "&ROUND(O14,1)&" labor hrs","Balanced Staffing")) -> Balanced Staffing
A15: Carlos | B15: 1 | C15: =Inputs!G16 -> 0 | D15: =IF($C15<>"x","",IFERROR(_xlfn.XLOOKUP($A15,'Staffing sheet 1ST Shift'!$A:$A,'Staffing sheet 1ST Shift'!$I:$I,""),"")) | E15: =Table200[[#This Row],[Recommended Task]] | H15: Loaders | I15: =COUNTIF(E2:E54, "Loading") -> 0 | K15: Outbound | L15: ='Staffing Forecast'!P13 -> 0 | N15: =Table2[[#This Row],[Available Staff ]]-Table2[[#This Row],[Needed ]] -> 0 | O15: =Table5[[#This Row],[Workers Gap]]*$I$3 -> 0 | P15: =IF(N15<0,"Understaffed",IF(N15=0,"Good","Overstaffed")) -> Good | Q15: =V4 -> 0 | R15: =1*I3*Table2[[#This Row],[Available Staff ]] -> 0 | S15: =Table4[[#This Row],[Expected Completed Cases]]/Table4[[#This Row],[Expected Volume]] -> #DIV/0! | T15: =IF($H15="Picking","PROTECT - PICKING BOTTLENECK",IF($P15="Understaffed","URGENT - ADD STAFF",IF(AND($P15="Overstaffed",$S15>=100%),"AVAILABLE TO MOVE",IF(AND($P15="Overstaffed",$S15<100%),"HIGH - DO NOT PULL","OK")))) -> #DIV/0! | U15: =IF(N15<0,"Need "&ROUND(ABS(N15),1)&" more workers / "&ROUND(ABS(O15),1)&" labor hrs",IF(N15>0,"Can move "&ROUND(N15,1)&" workers / "&ROUND(O15,1)&" labor hrs","Balanced Staffing")) -> Balanced Staffing
A16: Charles Myers | B16: 2 | C16: =Inputs!G17 -> 0 | D16: =IF($C16<>"x","",IFERROR(_xlfn.XLOOKUP($A16,'Staffing Sheet 2nd Shift'!$A:$A,'Staffing Sheet 2nd Shift'!$I:$I,""),"")) | E16: =Table200[[#This Row],[Recommended Task]] | H16: Total | I16: =SUM(I9:I15) -> 0 | L16: =ROUND(SUM(L9:L15),0) -> 4 | N16: =SUM(N9:N15) -> -4 | O16: =SUM(O9:O15) -> 0
A17: Chaz Lacey | B17: 2 | C17: =Inputs!G18 -> 0 | D17: =IF($C17<>"x","",IFERROR(_xlfn.XLOOKUP($A17,'Staffing Sheet 2nd Shift'!$A:$A,'Staffing Sheet 2nd Shift'!$I:$I,""),"")) | E17: =Table200[[#This Row],[Recommended Task]] | K17: =IF(L16>I16,"UnderStaffed",IF(L16=I16,"Good","Overstaffed")) -> UnderStaffed
A18: Chris Dodds | B18: 2 | C18: =Inputs!G19 -> 0 | D18: =IF($C18<>"x","",IFERROR(_xlfn.XLOOKUP($A18,'Staffing Sheet 2nd Shift'!$A:$A,'Staffing Sheet 2nd Shift'!$I:$I,""),"")) | E18: =Table200[[#This Row],[Recommended Task]]
A19: Cristopher R. | B19: 1 | C19: =Inputs!G20 -> 0 | D19: =IF($C19<>"x","",IFERROR(_xlfn.XLOOKUP($A19,'Staffing sheet 1ST Shift'!$A:$A,'Staffing sheet 1ST Shift'!$I:$I,""),"")) | E19: =Table200[[#This Row],[Recommended Task]]
A20: Dale Ferguson | B20: 1 | C20: =Inputs!G21 -> 0 | E20: =Table200[[#This Row],[Recommended Task]] -> 0
A21: Dale Hrenchir | B21: 1 | C21: =Inputs!G22 -> 0 | D21: =IF($C21<>"x","",IFERROR(_xlfn.XLOOKUP($A21,'Staffing sheet 1ST Shift'!$A:$A,'Staffing sheet 1ST Shift'!$I:$I,""),"")) | E21: =Table200[[#This Row],[Recommended Task]]
A22: Daniel V. | B22: 1 | C22: =Inputs!G23 -> 0 | D22: =IF($C22<>"x","",IFERROR(_xlfn.XLOOKUP($A22,'Staffing sheet 1ST Shift'!$A:$A,'Staffing sheet 1ST Shift'!$I:$I,""),"")) | E22: =Table200[[#This Row],[Recommended Task]]
A23: Danny Trotter | B23: 2 | C23: =Inputs!G24 -> 0 | D23: =IF($C23<>"x","",IFERROR(_xlfn.XLOOKUP($A23,'Staffing Sheet 2nd Shift'!$A:$A,'Staffing Sheet 2nd Shift'!$I:$I,""),"")) | E23: =Table200[[#This Row],[Recommended Task]] | H23: Staff Allocation Summary
A24: Daryl M | B24: 1 | C24: =Inputs!G25 -> 0 | D24: =IF($C24<>"x","",IFERROR(_xlfn.XLOOKUP($A24,'Staffing sheet 1ST Shift'!$A:$A,'Staffing sheet 1ST Shift'!$I:$I,""),"")) | E24: =Table200[[#This Row],[Recommended Task]] | H24: Priority | I24: Task | K24: Status | L24: Worker Gap | N24: Hours Gap | O24: Action
A25: Dashawn B. | B25: 1 | C25: =Inputs!G26 -> 0 | D25: =IF($C25<>"x","",IFERROR(_xlfn.XLOOKUP($A25,'Staffing sheet 1ST Shift'!$A:$A,'Staffing sheet 1ST Shift'!$I:$I,""),"")) | E25: =Table200[[#This Row],[Recommended Task]] | H25: =IF(L25<0,RANK(N25,$N$25:$N$31,1),"") -> 1 | I25: Unloaders | K25: =_xlfn.XLOOKUP(I25,$H$9:$H$15,$P$9:$P$15,"") -> Understaffed | L25: =_xlfn.XLOOKUP(I25,$H$9:$H$15,$N$9:$N$15,"") -> -2 | N25: =_xlfn.XLOOKUP(I25,$H$9:$H$15,$O$9:$O$15,"") -> 0 | O25: =IF(N9<0,"Need "&ROUND(ABS(N9),1)&" more workers / "&ROUND(ABS(O9),1)&" labor hrs",IF(N9>0,"Can move "&ROUND(N9,1)&" workers / "&ROUND(O9,1)&" labor hrs","Balanced Staffing")) -> Need 2 more workers / 0 labor hrs
A26: David Norwood | B26: 2 | C26: =Inputs!G27 -> 0 | D26: =IF($C26<>"x","",IFERROR(_xlfn.XLOOKUP($A26,'Staffing Sheet 2nd Shift'!$A:$A,'Staffing Sheet 2nd Shift'!$I:$I,""),"")) | E26: =Table200[[#This Row],[Recommended Task]] | H26: =IF(L26<0,RANK(N26,$N$25:$N$31,1),"") -> 1 | I26: Receivers | K26: =_xlfn.XLOOKUP(I26,$H$9:$H$15,$P$9:$P$15,"") -> Understaffed | L26: =_xlfn.XLOOKUP(I26,$H$9:$H$15,$N$9:$N$15,"") -> -2 | N26: =_xlfn.XLOOKUP(I26,$H$9:$H$15,$O$9:$O$15,"") -> 0 | O26: =IF(N10<0,"Need "&ROUND(ABS(N10),1)&" more workers / "&ROUND(ABS(O10),1)&" labor hrs",IF(N10>0,"Can move "&ROUND(N10,1)&" workers / "&ROUND(O10,1)&" labor hrs","Balanced Staffing")) -> Need 2 more workers / 0 labor hrs
A27: Diamond Williams | B27: 2 | C27: =Inputs!G28 -> 0 | D27: =IF($C27<>"x","",IFERROR(_xlfn.XLOOKUP($A27,'Staffing Sheet 2nd Shift'!$A:$A,'Staffing Sheet 2nd Shift'!$I:$I,""),"")) | E27: =Table200[[#This Row],[Recommended Task]] | H27: =IF(L27<0,RANK(N27,$N$25:$N$31,1),"") | I27: Putaway | K27: =_xlfn.XLOOKUP(I27,$H$9:$H$15,$P$9:$P$15,"") -> Good | L27: =_xlfn.XLOOKUP(I27,$H$9:$H$15,$N$9:$N$15,"") -> 0 | N27: =_xlfn.XLOOKUP(I27,$H$9:$H$15,$O$9:$O$15,"") -> 0 | O27: =IF(N11<0,"Need "&ROUND(ABS(N11),1)&" more workers / "&ROUND(ABS(O11),1)&" labor hrs",IF(N11>0,"Can move "&ROUND(N11,1)&" workers / "&ROUND(O11,1)&" labor hrs","Balanced Staffing")) -> Balanced Staffing
A28: Don Michael | B28: 2 | C28: =Inputs!G29 -> 0 | D28: =IF($C28<>"x","",IFERROR(_xlfn.XLOOKUP($A28,'Staffing Sheet 2nd Shift'!$A:$A,'Staffing Sheet 2nd Shift'!$I:$I,""),"")) | E28: =Table200[[#This Row],[Recommended Task]] | H28: =IF(L28<0,RANK(N28,$N$25:$N$31,1),"") | I28: Picking | K28: =P12 -> Good | L28: =N12 -> 0 | N28: =O12 -> 0 | O28: =IF(N12<0,"Need "&ROUND(ABS(N12),1)&" more workers / "&ROUND(ABS(O12),1)&" labor hrs",IF(N12>0,"Can move "&ROUND(N12,1)&" workers / "&ROUND(O12,1)&" labor hrs","Balanced Staffing")) -> Balanced Staffing
A29: Douglas W. | B29: 1 | C29: =Inputs!G30 -> 0 | D29: =IF($C29<>"x","",IFERROR(_xlfn.XLOOKUP($A29,'Staffing sheet 1ST Shift'!$A:$A,'Staffing sheet 1ST Shift'!$I:$I,""),"")) | E29: =Table200[[#This Row],[Recommended Task]] | H29: =IF(L29<0,RANK(N29,$N$25:$N$31,1),"") | I29: Replenishment | K29: =_xlfn.XLOOKUP(I29,$H$9:$H$15,$P$9:$P$15,"") -> Good | L29: =_xlfn.XLOOKUP(I29,$H$9:$H$15,$N$9:$N$15,"") -> 0 | N29: =_xlfn.XLOOKUP(I29,$H$9:$H$15,$O$9:$O$15,"") -> 0 | O29: =IF(N13<0,"Need "&ROUND(ABS(N13),1)&" more workers / "&ROUND(ABS(O13),1)&" labor hrs",IF(N13>0,"Can move "&ROUND(N13,1)&" workers / "&ROUND(O13,1)&" labor hrs","Balanced Staffing")) -> Balanced Staffing
A30: Dwayne A. | B30: 1 | C30: =Inputs!G31 -> 0 | D30: =IF($C30<>"x","",IFERROR(_xlfn.XLOOKUP($A30,'Staffing sheet 1ST Shift'!$A:$A,'Staffing sheet 1ST Shift'!$I:$I,""),"")) | E30: =Table200[[#This Row],[Recommended Task]] | H30: =IF(L30<0,RANK(N30,$N$25:$N$31,1),"") | I30: Full Pallet Pullers | K30: =_xlfn.XLOOKUP(I30,$H$9:$H$15,$P$9:$P$15,"") -> Good | L30: =_xlfn.XLOOKUP(I30,$H$9:$H$15,$N$9:$N$15,"") -> 0 | N30: =_xlfn.XLOOKUP(I30,$H$9:$H$15,$O$9:$O$15,"") -> 0 | O30: =IF(N14<0,"Need "&ROUND(ABS(N14),1)&" more workers / "&ROUND(ABS(O14),1)&" labor hrs",IF(N14>0,"Can move "&ROUND(N14,1)&" workers / "&ROUND(O14,1)&" labor hrs","Balanced Staffing")) -> Balanced Staffing
A31: Dylan | B31: 1 | C31: =Inputs!G32 -> 0 | D31: =IF($C31<>"x","",IFERROR(_xlfn.XLOOKUP($A31,'Staffing sheet 1ST Shift'!$A:$A,'Staffing sheet 1ST Shift'!$I:$I,""),"")) | E31: =Table200[[#This Row],[Recommended Task]] | H31: =IF(L31<0,RANK(N31,$N$25:$N$31,1),"") | I31: Loaders | K31: =_xlfn.XLOOKUP(I31,$H$9:$H$15,$P$9:$P$15,"") -> Good | L31: =_xlfn.XLOOKUP(I31,$H$9:$H$15,$N$9:$N$15,"") -> 0 | N31: =_xlfn.XLOOKUP(I31,$H$9:$H$15,$O$9:$O$15,"") -> 0 | O31: =IF(N15<0,"Need "&ROUND(ABS(N15),1)&" more workers / "&ROUND(ABS(O15),1)&" labor hrs",IF(N15>0,"Can move "&ROUND(N15,1)&" workers / "&ROUND(O15,1)&" labor hrs","Balanced Staffing")) -> Balanced Staffing
A32: Earnest Carter | B32: 2 | C32: =Inputs!G33 -> 0 | D32: =IF($C32<>"x","",IFERROR(_xlfn.XLOOKUP($A32,'Staffing Sheet 2nd Shift'!$A:$A,'Staffing Sheet 2nd Shift'!$I:$I,""),"")) | E32: =Table200[[#This Row],[Recommended Task]]
A33: Eugene Emery | B33: 2 | C33: =Inputs!G34 -> 0 | D33: =IF($C33<>"x","",IFERROR(_xlfn.XLOOKUP($A33,'Staffing Sheet 2nd Shift'!$A:$A,'Staffing Sheet 2nd Shift'!$I:$I,""),"")) | E33: =Table200[[#This Row],[Recommended Task]]
A34: Everardo G. | B34: 1 | C34: =Inputs!G35 -> 0 | D34: =IF($C34<>"x","",IFERROR(_xlfn.XLOOKUP($A34,'Staffing sheet 1ST Shift'!$A:$A,'Staffing sheet 1ST Shift'!$I:$I,""),"")) | E34: =Table200[[#This Row],[Recommended Task]]
A35: Felipe P. | B35: 1 | C35: =Inputs!G36 -> 0 | D35: =IF($C35<>"x","",IFERROR(_xlfn.XLOOKUP($A35,'Staffing sheet 1ST Shift'!$A:$A,'Staffing sheet 1ST Shift'!$I:$I,""),"")) | E35: =Table200[[#This Row],[Recommended Task]]
A36: Francisco N. | B36: 1 | C36: =Inputs!G37 -> 0 | D36: =IF($C36<>"x","",IFERROR(_xlfn.XLOOKUP($A36,'Staffing sheet 1ST Shift'!$A:$A,'Staffing sheet 1ST Shift'!$I:$I,""),"")) | E36: =Table200[[#This Row],[Recommended Task]]
A37: Gary Lake | B37: 2 | C37: =Inputs!G38 -> 0 | D37: =IF($C37<>"x","",IFERROR(_xlfn.XLOOKUP($A37,'Staffing Sheet 2nd Shift'!$A:$A,'Staffing Sheet 2nd Shift'!$I:$I,""),"")) | E37: =Table200[[#This Row],[Recommended Task]]
A38: Goliath Haagan | B38: 2 | C38: =Inputs!G39 -> 0 | D38: =IF($C38<>"x","",IFERROR(_xlfn.XLOOKUP($A38,'Staffing Sheet 2nd Shift'!$A:$A,'Staffing Sheet 2nd Shift'!$I:$I,""),"")) | E38: =Table200[[#This Row],[Recommended Task]]
A39: Henry | B39: 1 | C39: =Inputs!G40 -> 0 | D39: =IF($C39<>"x","",IFERROR(_xlfn.XLOOKUP($A39,'Staffing sheet 1ST Shift'!$A:$A,'Staffing sheet 1ST Shift'!$I:$I,""),"")) | E39: =Table200[[#This Row],[Recommended Task]]
A40: Isaiah Kilmete | B40: 2 | C40: =Inputs!G41 -> 0 | D40: =IF($C40<>"x","",IFERROR(_xlfn.XLOOKUP($A40,'Staffing Sheet 2nd Shift'!$A:$A,'Staffing Sheet 2nd Shift'!$I:$I,""),"")) | E40: =Table200[[#This Row],[Recommended Task]]
...

Sheet Staffing Forecast
B2: Day | C2: =Inputs!B1 -> 0 | E2: HOURS AVAILABLE | H2: HOURS NEEDED
B3: Shift | C3: =Inputs!B2 -> 0 | E3: =C27*C4 -> 0 | H3: =D27*C4 -> 38
B4: Shift Hours Remaining | C4: =Inputs!B4 -> 9.5
B5: Total Cases to Pick | C5: =Inputs!B5 -> 0
B6: Total Pallets to Pull | C6: =Inputs!B6 -> 0
B7: Total Replenishments | C7: =C5/70 -> 0
B8: Total Outbounds | C8: =Inputs!B7 -> 0
B9: Crossroads Running | C9: =Inputs!B8 -> 0 | F9: OUTBOUND STAFFING | T9: INBOUND STAFFING NEEDS
B10: Deer Creek Running | C10: =Inputs!B9 -> 0
B11: MSB Running | C11: =Inputs!B10 -> 0 | F11: Total Pallets to Pull | G11: # Drivers Needed | I11: Total Cases to Pick | J11: # Pickers Needed | L11: Pallets to Replenish | M11: # Replen Needed | O11: Trailers to Load | P11: # Loaders Needed | T11: Total Pallets to Unload | U11: # Unloaders Needed | W11: Total Pallets to Putaway | X11: # Putaways Needed
B12: Cases Picked Per Hr | C12: 185
B13: Pallets Pulled Per Hr | C13: 25 | F13: =C6 -> 0 | G13: =C6/(25*C4) -> 0 | I13: =C5 -> 0 | J13: =C5/(185*C4) -> 0 | L13: =C7 -> 0 | M13: =C7/(25*C4) -> 0 | O13: =C8 -> 0 | P13: =C8/(1*C4) -> 0 | T13: =(C9="YES")*('Percentage Data'!R21)+(C10="YES")*('Percentage Data'!R22)+(C11="YES")*('Percentage Data'!R23) -> 0 | U13: =((((C9="YES")*('Percentage Data'!R21)+(C10="YES")*('Percentage Data'!R22)+(C11="YES")*('Percentage Data'!R23))/C4)/C14)/2 -> 0 | W13: =(C9="YES")*('Percentage Data'!R21)+(C10="YES")*('Percentage Data'!R22)+(C11="YES")*('Percentage Data'!R23) -> 0 | X13: =((W13/C4)/C15)/2 -> 0 | AB13: =T13 -> 0 | AC13: =AB13 -> 0
B14: Pallets Unloaded Per Hr | C14: 44 | U14: =((((#REF!="YES")*('Percentage Data'!AC4)+(#REF!="YES")*('Percentage Data'!AC5)+(#REF!="YES")*('Percentage Data'!AC6))/#REF!)/#REF!)/2 -> #REF! | X14: =((W9/#REF!)/C5)/2 -> #REF!
B15: Pallet Putaway Per Hr | C15: 25
B16: Loads Per Hour | C16: 1
B19: Positions | C19: Available | D19: Needed
B20: Unloaders | C20: ='Crew Sheet'!I9 -> 0 | D20: =2 -> 2
B21: Receivers | C21: ='Crew Sheet'!I10 -> 0 | D21: =2 -> 2
B22: Putaway | C22: ='Crew Sheet'!I11 -> 0 | D22: =X13 -> 0
B23: Case Pickers | C23: ='Crew Sheet'!I12 -> 0 | D23: =J13 -> 0
B24: Replenishment | C24: ='Crew Sheet'!I13 -> 0 | D24: =M13 -> 0
B25: Full Pallet Pullers | C25: ='Crew Sheet'!I14 -> 0 | D25: =G13 -> 0
B26: Loaders | C26: ='Crew Sheet'!I15 -> 0 | D26: =P13 -> 0
B27: TOTALS | C27: =SUM(C20:C26) -> 0 | D27: =ROUND(SUM(D20:D26),0) -> 4

Sheet Staffing Dashboard

Sheet Staffing sheet 1ST Shift
A1: Name | B1: Shift | C1: Weekday/Weekend | D1: Skills | E1: Forklift Certified | F1: Best Fit | G1: Classification | H1: Present | I1: Recommended Task | K1: Skills | L1: Classification | M1: Yes | N1: Standard | O1: Value | R1: Weekday | S1: 1st | T1: Present | U1: Picking Score | V1: Loader Score | W1: Tasker Score | X1: Unloading Score | Y1: Reeceiving Score
A2: Douglas W. | B2: 1st | C2: Weekend | D2: T/L | E2: Yes | F2: Loading | H2: =IFERROR(VLOOKUP($A2,'Crew Sheet'!#REF!,2,FALSE),"") | I2: =IF($T2<>"x","", IF(TRIM($D2)="P","Picking", IF(AND(COUNTIF($F2,"*Unload*"),COUNTIF($D2,"*U*")),"Unloading", IF(AND(COUNTIF($D2,"*L*"),COUNTIFS($I$1:I1,"Loading",$T$1:T1,"x")<ROUNDUP(_xlfn.XLOOKUP("Loaders",'Crew Sheet'!$H:$H,'Crew Sheet'!$L:$L),0)),"Loading", IF(AND(COUNTIF($D2,"*R*"),COUNTIFS($I$1:I1,"Receiving",$T$1:T1,"x")<ROUNDUP(SUM('Crew Sheet'!$L$10:$L$11),0)),"Receiving", IF(AND(COUNTIF($F2,"*Pick*"),COUNTIF($D2,"*P*")),"Picking", IF(AND(COUNTIF($F2,"*Task*"),COUNTIF($D2,"*T*")),"Replen/Pallets/Putaways", IF(COUNTIF($D2,"*T*"),"Replen/Pallets/Putaways","Lead/Extra")))))))) | K2: Picking | L2: Below Average | M2: No | N2: Pulls x hour | O2: 25 | R2: Weekend | S2: 2nd | T2: =IFERROR(VLOOKUP($A2,'Crew Sheet'!$A:$C,2,FALSE),"") -> 1 | U2: =IF($T2<>"x",-999,IF(IFERROR(ISNUMBER(SEARCH("P",$D2)),FALSE),100,0)+IF(IFERROR(ISNUMBER(SEARCH("Pick",$F2)),FALSE),1000,0)+IF($G2="Above Average",100,IF($G2="Average",50,0))) -> -999 | V2: =IF($T2<>"x",-999,IF(IFERROR(ISNUMBER(SEARCH("L",$D2)),FALSE),100,0)+IF(IFERROR(ISNUMBER(SEARCH("Load",$F2)),FALSE),1000,0)+IF($G2="Above Average",100,IF($G2="Average",50,0))) -> -999 | W2: =IF($T2<>"x",-999,IF(IFERROR(ISNUMBER(SEARCH("T",$D2)),FALSE),100,0)+IF(OR(IFERROR(ISNUMBER(SEARCH("Task",$F2)),FALSE),IFERROR(ISNUMBER(SEARCH("Putaway",$F2)),FALSE),IFERROR(ISNUMBER(SEARCH("Replen",$F2)),FALSE),IFERROR(ISNUMBER(SEARCH("Full Pallet",$F2)),FALSE)),1000,0)+IF($G2="Above Average",100,IF($G2="Average",50,0))) -> -999 | X2: =IF($T2<>"x",-999,IF(IFERROR(ISNUMBER(SEARCH("U",$D2)),FALSE),100,0)+IF(IFERROR(ISNUMBER(SEARCH("Unload",$F2)),FALSE),1000,0)+IF($G2="Above Average",100,IF($G2="Average",50,0))) -> -999 | Y2: =IF($T2<>"x",-999,IF(IFERROR(ISNUMBER(SEARCH("R",$D2)),FALSE),100,0)+IF(IFERROR(ISNUMBER(SEARCH("Receiv",$F2)),FALSE),1000,0)+IF($G2="Above Average",100,IF($G2="Average",50,0))) -> -999
A3: Dwayne A. | B3: 1st | C3: Weekend | D3: P/T/R/L | E3: Yes | F3: Loading | H3: =IFERROR(VLOOKUP($A3,'Crew Sheet'!#REF!,2,FALSE),"") | I3: =IF($T3<>"x","", IF(TRIM($D3)="P","Picking", IF(AND(COUNTIF($F3,"*Unload*"),COUNTIF($D3,"*U*")),"Unloading", IF(AND(COUNTIF($D3,"*L*"),COUNTIFS($I$1:I2,"Loading",$T$1:T2,"x")<ROUNDUP(_xlfn.XLOOKUP("Loaders",'Crew Sheet'!$H:$H,'Crew Sheet'!$L:$L),0)),"Loading", IF(AND(COUNTIF($D3,"*R*"),COUNTIFS($I$1:I2,"Receiving",$T$1:T2,"x")<ROUNDUP(SUM('Crew Sheet'!$L$10:$L$11),0)),"Receiving", IF(AND(COUNTIF($F3,"*Pick*"),COUNTIF($D3,"*P*")),"Picking", IF(AND(COUNTIF($F3,"*Task*"),COUNTIF($D3,"*T*")),"Replen/Pallets/Putaways", IF(COUNTIF($D3,"*T*"),"Replen/Pallets/Putaways","Lead/Extra")))))))) | K3: Unloading | L3: Average | N3: Picks x hour | O3: 185 | T3: =IFERROR(VLOOKUP($A3,'Crew Sheet'!$A:$C,2,FALSE),"") -> 1 | U3: =IF($T3<>"x",-999,IF(IFERROR(ISNUMBER(SEARCH("P",$D3)),FALSE),100,0)+IF(IFERROR(ISNUMBER(SEARCH("Pick",$F3)),FALSE),1000,0)+IF($G3="Above Average",100,IF($G3="Average",50,0))) -> -999 | V3: =IF($T3<>"x",-999,IF(IFERROR(ISNUMBER(SEARCH("L",$D3)),FALSE),100,0)+IF(IFERROR(ISNUMBER(SEARCH("Load",$F3)),FALSE),1000,0)+IF($G3="Above Average",100,IF($G3="Average",50,0))) -> -999 | W3: =IF($T3<>"x",-999,IF(IFERROR(ISNUMBER(SEARCH("T",$D3)),FALSE),100,0)+IF(OR(IFERROR(ISNUMBER(SEARCH("Task",$F3)),FALSE),IFERROR(ISNUMBER(SEARCH("Putaway",$F3)),FALSE),IFERROR(ISNUMBER(SEARCH("Replen",$F3)),FALSE),IFERROR(ISNUMBER(SEARCH("Full Pallet",$F3)),FALSE)),1000,0)+IF($G3="Above Average",100,IF($G3="Average",50,0))) -> -999 | X3: =IF($T3<>"x",-999,IF(IFERROR(ISNUMBER(SEARCH("U",$D3)),FALSE),100,0)+IF(IFERROR(ISNUMBER(SEARCH("Unload",$F3)),FALSE),1000,0)+IF($G3="Above Average",100,IF($G3="Average",50,0))) -> -999 | Y3: =IF($T3<>"x",-999,IF(IFERROR(ISNUMBER(SEARCH("R",$D3)),FALSE),100,0)+IF(IFERROR(ISNUMBER(SEARCH("Receiv",$F3)),FALSE),1000,0)+IF($G3="Above Average",100,IF($G3="Average",50,0))) -> -999
A4: Joe M. | B4: 1st | C4: Weekend | D4: T/L | E4: Yes | F4: Loading | H4: =IFERROR(VLOOKUP($A4,'Crew Sheet'!#REF!,2,FALSE),"") | I4: =IF($T4<>"x","", IF(TRIM($D4)="P","Picking", IF(AND(COUNTIF($F4,"*Unload*"),COUNTIF($D4,"*U*")),"Unloading", IF(AND(COUNTIF($D4,"*L*"),COUNTIFS($I$1:I3,"Loading",$T$1:T3,"x")<ROUNDUP(_xlfn.XLOOKUP("Loaders",'Crew Sheet'!$H:$H,'Crew Sheet'!$L:$L),0)),"Loading", IF(AND(COUNTIF($D4,"*R*"),COUNTIFS($I$1:I3,"Receiving",$T$1:T3,"x")<ROUNDUP(SUM('Crew Sheet'!$L$10:$L$11),0)),"Receiving", IF(AND(COUNTIF($F4,"*Pick*"),COUNTIF($D4,"*P*")),"Picking", IF(AND(COUNTIF($F4,"*Task*"),COUNTIF($D4,"*T*")),"Replen/Pallets/Putaways", IF(COUNTIF($D4,"*T*"),"Replen/Pallets/Putaways","Lead/Extra")))))))) | K4: Receiving | L4: Above Average | N4: Loads x hour | O4: 1 | T4: =IFERROR(VLOOKUP($A4,'Crew Sheet'!$A:$C,2,FALSE),"") -> 1 | U4: =IF($T4<>"x",-999,IF(IFERROR(ISNUMBER(SEARCH("P",$D4)),FALSE),100,0)+IF(IFERROR(ISNUMBER(SEARCH("Pick",$F4)),FALSE),1000,0)+IF($G4="Above Average",100,IF($G4="Average",50,0))) -> -999 | V4: =IF($T4<>"x",-999,IF(IFERROR(ISNUMBER(SEARCH("L",$D4)),FALSE),100,0)+IF(IFERROR(ISNUMBER(SEARCH("Load",$F4)),FALSE),1000,0)+IF($G4="Above Average",100,IF($G4="Average",50,0))) -> -999 | W4: =IF($T4<>"x",-999,IF(IFERROR(ISNUMBER(SEARCH("T",$D4)),FALSE),100,0)+IF(OR(IFERROR(ISNUMBER(SEARCH("Task",$F4)),FALSE),IFERROR(ISNUMBER(SEARCH("Putaway",$F4)),FALSE),IFERROR(ISNUMBER(SEARCH("Replen",$F4)),FALSE),IFERROR(ISNUMBER(SEARCH("Full Pallet",$F4)),FALSE)),1000,0)+IF($G4="Above Average",100,IF($G4="Average",50,0))) -> -999 | X4: =IF($T4<>"x",-999,IF(IFERROR(ISNUMBER(SEARCH("U",$D4)),FALSE),100,0)+IF(IFERROR(ISNUMBER(SEARCH("Unload",$F4)),FALSE),1000,0)+IF($G4="Above Average",100,IF($G4="Average",50,0))) -> -999 | Y4: =IF($T4<>"x",-999,IF(IFERROR(ISNUMBER(SEARCH("R",$D4)),FALSE),100,0)+IF(IFERROR(ISNUMBER(SEARCH("Receiv",$F4)),FALSE),1000,0)+IF($G4="Above Average",100,IF($G4="Average",50,0))) -> -999
A5: Jose G. | B5: 1st | C5: Weekend | D5: T/L | E5: Yes | F5: Loading | H5: =IFERROR(VLOOKUP($A5,'Crew Sheet'!#REF!,2,FALSE),"") | I5: =IF($T5<>"x","", IF(TRIM($D5)="P","Picking", IF(AND(COUNTIF($F5,"*Unload*"),COUNTIF($D5,"*U*")),"Unloading", IF(AND(COUNTIF($D5,"*L*"),COUNTIFS($I$1:I4,"Loading",$T$1:T4,"x")<ROUNDUP(_xlfn.XLOOKUP("Loaders",'Crew Sheet'!$H:$H,'Crew Sheet'!$L:$L),0)),"Loading", IF(AND(COUNTIF($D5,"*R*"),COUNTIFS($I$1:I4,"Receiving",$T$1:T4,"x")<ROUNDUP(SUM('Crew Sheet'!$L$10:$L$11),0)),"Receiving", IF(AND(COUNTIF($F5,"*Pick*"),COUNTIF($D5,"*P*")),"Picking", IF(AND(COUNTIF($F5,"*Task*"),COUNTIF($D5,"*T*")),"Replen/Pallets/Putaways", IF(COUNTIF($D5,"*T*"),"Replen/Pallets/Putaways","Lead/Extra")))))))) | K5: Loading | N5: Pallets Unloaded x hour | T5: =IFERROR(VLOOKUP($A5,'Crew Sheet'!$A:$C,2,FALSE),"") -> 1 | U5: =IF($T5<>"x",-999,IF(IFERROR(ISNUMBER(SEARCH("P",$D5)),FALSE),100,0)+IF(IFERROR(ISNUMBER(SEARCH("Pick",$F5)),FALSE),1000,0)+IF($G5="Above Average",100,IF($G5="Average",50,0))) -> -999 | V5: =IF($T5<>"x",-999,IF(IFERROR(ISNUMBER(SEARCH("L",$D5)),FALSE),100,0)+IF(IFERROR(ISNUMBER(SEARCH("Load",$F5)),FALSE),1000,0)+IF($G5="Above Average",100,IF($G5="Average",50,0))) -> -999 | W5: =IF($T5<>"x",-999,IF(IFERROR(ISNUMBER(SEARCH("T",$D5)),FALSE),100,0)+IF(OR(IFERROR(ISNUMBER(SEARCH("Task",$F5)),FALSE),IFERROR(ISNUMBER(SEARCH("Putaway",$F5)),FALSE),IFERROR(ISNUMBER(SEARCH("Replen",$F5)),FALSE),IFERROR(ISNUMBER(SEARCH("Full Pallet",$F5)),FALSE)),1000,0)+IF($G5="Above Average",100,IF($G5="Average",50,0))) -> -999 | X5: =IF($T5<>"x",-999,IF(IFERROR(ISNUMBER(SEARCH("U",$D5)),FALSE),100,0)+IF(IFERROR(ISNUMBER(SEARCH("Unload",$F5)),FALSE),1000,0)+IF($G5="Above Average",100,IF($G5="Average",50,0))) -> -999 | Y5: =IF($T5<>"x",-999,IF(IFERROR(ISNUMBER(SEARCH("R",$D5)),FALSE),100,0)+IF(IFERROR(ISNUMBER(SEARCH("Receiv",$F5)),FALSE),1000,0)+IF($G5="Above Average",100,IF($G5="Average",50,0))) -> -999
A6: Pablo H. | B6: 1st | C6: Weekday | D6: T/L | E6: Yes | F6: Loading | H6: =IFERROR(VLOOKUP($A6,'Crew Sheet'!#REF!,2,FALSE),"") | I6: =IF($T6<>"x","", IF(TRIM($D6)="P","Picking", IF(AND(COUNTIF($F6,"*Unload*"),COUNTIF($D6,"*U*")),"Unloading", IF(AND(COUNTIF($D6,"*L*"),COUNTIFS($I$1:I5,"Loading",$T$1:T5,"x")<ROUNDUP(_xlfn.XLOOKUP("Loaders",'Crew Sheet'!$H:$H,'Crew Sheet'!$L:$L),0)),"Loading", IF(AND(COUNTIF($D6,"*R*"),COUNTIFS($I$1:I5,"Receiving",$T$1:T5,"x")<ROUNDUP(SUM('Crew Sheet'!$L$10:$L$11),0)),"Receiving", IF(AND(COUNTIF($F6,"*Pick*"),COUNTIF($D6,"*P*")),"Picking", IF(AND(COUNTIF($F6,"*Task*"),COUNTIF($D6,"*T*")),"Replen/Pallets/Putaways", IF(COUNTIF($D6,"*T*"),"Replen/Pallets/Putaways","Lead/Extra")))))))) | K6: Tasking | T6: =IFERROR(VLOOKUP($A6,'Crew Sheet'!$A:$C,2,FALSE),"") -> 1 | U6: =IF($T6<>"x",-999,IF(IFERROR(ISNUMBER(SEARCH("P",$D6)),FALSE),100,0)+IF(IFERROR(ISNUMBER(SEARCH("Pick",$F6)),FALSE),1000,0)+IF($G6="Above Average",100,IF($G6="Average",50,0))) -> -999 | V6: =IF($T6<>"x",-999,IF(IFERROR(ISNUMBER(SEARCH("L",$D6)),FALSE),100,0)+IF(IFERROR(ISNUMBER(SEARCH("Load",$F6)),FALSE),1000,0)+IF($G6="Above Average",100,IF($G6="Average",50,0))) -> -999 | W6: =IF($T6<>"x",-999,IF(IFERROR(ISNUMBER(SEARCH("T",$D6)),FALSE),100,0)+IF(OR(IFERROR(ISNUMBER(SEARCH("Task",$F6)),FALSE),IFERROR(ISNUMBER(SEARCH("Putaway",$F6)),FALSE),IFERROR(ISNUMBER(SEARCH("Replen",$F6)),FALSE),IFERROR(ISNUMBER(SEARCH("Full Pallet",$F6)),FALSE)),1000,0)+IF($G6="Above Average",100,IF($G6="Average",50,0))) -> -999 | X6: =IF($T6<>"x",-999,IF(IFERROR(ISNUMBER(SEARCH("U",$D6)),FALSE),100,0)+IF(IFERROR(ISNUMBER(SEARCH("Unload",$F6)),FALSE),1000,0)+IF($G6="Above Average",100,IF($G6="Average",50,0))) -> -999 | Y6: =IF($T6<>"x",-999,IF(IFERROR(ISNUMBER(SEARCH("R",$D6)),FALSE),100,0)+IF(IFERROR(ISNUMBER(SEARCH("Receiv",$F6)),FALSE),1000,0)+IF($G6="Above Average",100,IF($G6="Average",50,0))) -> -999
A7: Anthony T | B7: 1st | C7: Weekend | D7: P | E7: Yes | F7: Picking | H7: =IFERROR(VLOOKUP($A7,'Crew Sheet'!#REF!,2,FALSE),"") | I7: =IF($T7<>"x","", IF(TRIM($D7)="P","Picking", IF(AND(COUNTIF($F7,"*Unload*"),COUNTIF($D7,"*U*")),"Unloading", IF(AND(COUNTIF($D7,"*L*"),COUNTIFS($I$1:I6,"Loading",$T$1:T6,"x")<ROUNDUP(_xlfn.XLOOKUP("Loaders",'Crew Sheet'!$H:$H,'Crew Sheet'!$L:$L),0)),"Loading", IF(AND(COUNTIF($D7,"*R*"),COUNTIFS($I$1:I6,"Receiving",$T$1:T6,"x")<ROUNDUP(SUM('Crew Sheet'!$L$10:$L$11),0)),"Receiving", IF(AND(COUNTIF($F7,"*Pick*"),COUNTIF($D7,"*P*")),"Picking", IF(AND(COUNTIF($F7,"*Task*"),COUNTIF($D7,"*T*")),"Replen/Pallets/Putaways", IF(COUNTIF($D7,"*T*"),"Replen/Pallets/Putaways","Lead/Extra")))))))) | T7: =IFERROR(VLOOKUP($A7,'Crew Sheet'!$A:$C,2,FALSE),"") -> 1 | U7: =IF($T7<>"x",-999,IF(IFERROR(ISNUMBER(SEARCH("P",$D7)),FALSE),100,0)+IF(IFERROR(ISNUMBER(SEARCH("Pick",$F7)),FALSE),1000,0)+IF($G7="Above Average",100,IF($G7="Average",50,0))) -> -999 | V7: =IF($T7<>"x",-999,IF(IFERROR(ISNUMBER(SEARCH("L",$D7)),FALSE),100,0)+IF(IFERROR(ISNUMBER(SEARCH("Load",$F7)),FALSE),1000,0)+IF($G7="Above Average",100,IF($G7="Average",50,0))) -> -999 | W7: =IF($T7<>"x",-999,IF(IFERROR(ISNUMBER(SEARCH("T",$D7)),FALSE),100,0)+IF(OR(IFERROR(ISNUMBER(SEARCH("Task",$F7)),FALSE),IFERROR(ISNUMBER(SEARCH("Putaway",$F7)),FALSE),IFERROR(ISNUMBER(SEARCH("Replen",$F7)),FALSE),IFERROR(ISNUMBER(SEARCH("Full Pallet",$F7)),FALSE)),1000,0)+IF($G7="Above Average",100,IF($G7="Average",50,0))) -> -999 | X7: =IF($T7<>"x",-999,IF(IFERROR(ISNUMBER(SEARCH("U",$D7)),FALSE),100,0)+IF(IFERROR(ISNUMBER(SEARCH("Unload",$F7)),FALSE),1000,0)+IF($G7="Above Average",100,IF($G7="Average",50,0))) -> -999 | Y7: =IF($T7<>"x",-999,IF(IFERROR(ISNUMBER(SEARCH("R",$D7)),FALSE),100,0)+IF(IFERROR(ISNUMBER(SEARCH("Receiv",$F7)),FALSE),1000,0)+IF($G7="Above Average",100,IF($G7="Average",50,0))) -> -999
A8: Ariel | B8: 1st | C8: Weekend | D8: P | E8: No | F8: Picking | H8: =IFERROR(VLOOKUP($A8,'Crew Sheet'!#REF!,2,FALSE),"") | I8: =IF($T8<>"x","", IF(TRIM($D8)="P","Picking", IF(AND(COUNTIF($F8,"*Unload*"),COUNTIF($D8,"*U*")),"Unloading", IF(AND(COUNTIF($D8,"*L*"),COUNTIFS($I$1:I7,"Loading",$T$1:T7,"x")<ROUNDUP(_xlfn.XLOOKUP("Loaders",'Crew Sheet'!$H:$H,'Crew Sheet'!$L:$L),0)),"Loading", IF(AND(COUNTIF($D8,"*R*"),COUNTIFS($I$1:I7,"Receiving",$T$1:T7,"x")<ROUNDUP(SUM('Crew Sheet'!$L$10:$L$11),0)),"Receiving", IF(AND(COUNTIF($F8,"*Pick*"),COUNTIF($D8,"*P*")),"Picking", IF(AND(COUNTIF($F8,"*Task*"),COUNTIF($D8,"*T*")),"Replen/Pallets/Putaways", IF(COUNTIF($D8,"*T*"),"Replen/Pallets/Putaways","Lead/Extra")))))))) | N8: Picking | O8: P | T8: =IFERROR(VLOOKUP($A8,'Crew Sheet'!$A:$C,2,FALSE),"") -> 1 | U8: =IF($T8<>"x",-999,IF(IFERROR(ISNUMBER(SEARCH("P",$D8)),FALSE),100,0)+IF(IFERROR(ISNUMBER(SEARCH("Pick",$F8)),FALSE),1000,0)+IF($G8="Above Average",100,IF($G8="Average",50,0))) -> -999 | V8: =IF($T8<>"x",-999,IF(IFERROR(ISNUMBER(SEARCH("L",$D8)),FALSE),100,0)+IF(IFERROR(ISNUMBER(SEARCH("Load",$F8)),FALSE),1000,0)+IF($G8="Above Average",100,IF($G8="Average",50,0))) -> -999 | W8: =IF($T8<>"x",-999,IF(IFERROR(ISNUMBER(SEARCH("T",$D8)),FALSE),100,0)+IF(OR(IFERROR(ISNUMBER(SEARCH("Task",$F8)),FALSE),IFERROR(ISNUMBER(SEARCH("Putaway",$F8)),FALSE),IFERROR(ISNUMBER(SEARCH("Replen",$F8)),FALSE),IFERROR(ISNUMBER(SEARCH("Full Pallet",$F8)),FALSE)),1000,0)+IF($G8="Above Average",100,IF($G8="Average",50,0))) -> -999 | X8: =IF($T8<>"x",-999,IF(IFERROR(ISNUMBER(SEARCH("U",$D8)),FALSE),100,0)+IF(IFERROR(ISNUMBER(SEARCH("Unload",$F8)),FALSE),1000,0)+IF($G8="Above Average",100,IF($G8="Average",50,0))) -> -999 | Y8: =IF($T8<>"x",-999,IF(IFERROR(ISNUMBER(SEARCH("R",$D8)),FALSE),100,0)+IF(IFERROR(ISNUMBER(SEARCH("Receiv",$F8)),FALSE),1000,0)+IF($G8="Above Average",100,IF($G8="Average",50,0))) -> -999
A9: Brett W. | B9: 1st | C9: Weekday | D9: P/T | E9: Yes | F9: Picking | H9: =IFERROR(VLOOKUP($A9,'Crew Sheet'!#REF!,2,FALSE),"") | I9: =IF($T9<>"x","", IF(TRIM($D9)="P","Picking", IF(AND(COUNTIF($F9,"*Unload*"),COUNTIF($D9,"*U*")),"Unloading", IF(AND(COUNTIF($D9,"*L*"),COUNTIFS($I$1:I8,"Loading",$T$1:T8,"x")<ROUNDUP(_xlfn.XLOOKUP("Loaders",'Crew Sheet'!$H:$H,'Crew Sheet'!$L:$L),0)),"Loading", IF(AND(COUNTIF($D9,"*R*"),COUNTIFS($I$1:I8,"Receiving",$T$1:T8,"x")<ROUNDUP(SUM('Crew Sheet'!$L$10:$L$11),0)),"Receiving", IF(AND(COUNTIF($F9,"*Pick*"),COUNTIF($D9,"*P*")),"Picking", IF(AND(COUNTIF($F9,"*Task*"),COUNTIF($D9,"*T*")),"Replen/Pallets/Putaways", IF(COUNTIF($D9,"*T*"),"Replen/Pallets/Putaways","Lead/Extra")))))))) | N9: Receiving | O9: R | T9: =IFERROR(VLOOKUP($A9,'Crew Sheet'!$A:$C,2,FALSE),"") -> 1 | U9: =IF($T9<>"x",-999,IF(IFERROR(ISNUMBER(SEARCH("P",$D9)),FALSE),100,0)+IF(IFERROR(ISNUMBER(SEARCH("Pick",$F9)),FALSE),1000,0)+IF($G9="Above Average",100,IF($G9="Average",50,0))) -> -999 | V9: =IF($T9<>"x",-999,IF(IFERROR(ISNUMBER(SEARCH("L",$D9)),FALSE),100,0)+IF(IFERROR(ISNUMBER(SEARCH("Load",$F9)),FALSE),1000,0)+IF($G9="Above Average",100,IF($G9="Average",50,0))) -> -999 | W9: =IF($T9<>"x",-999,IF(IFERROR(ISNUMBER(SEARCH("T",$D9)),FALSE),100,0)+IF(OR(IFERROR(ISNUMBER(SEARCH("Task",$F9)),FALSE),IFERROR(ISNUMBER(SEARCH("Putaway",$F9)),FALSE),IFERROR(ISNUMBER(SEARCH("Replen",$F9)),FALSE),IFERROR(ISNUMBER(SEARCH("Full Pallet",$F9)),FALSE)),1000,0)+IF($G9="Above Average",100,IF($G9="Average",50,0))) -> -999 | X9: =IF($T9<>"x",-999,IF(IFERROR(ISNUMBER(SEARCH("U",$D9)),FALSE),100,0)+IF(IFERROR(ISNUMBER(SEARCH("Unload",$F9)),FALSE),1000,0)+IF($G9="Above Average",100,IF($G9="Average",50,0))) -> -999 | Y9: =IF($T9<>"x",-999,IF(IFERROR(ISNUMBER(SEARCH("R",$D9)),FALSE),100,0)+IF(IFERROR(ISNUMBER(SEARCH("Receiv",$F9)),FALSE),1000,0)+IF($G9="Above Average",100,IF($G9="Average",50,0))) -> -999
A10: Daniel V. | B10: 1st | C10: Weekday | D10: P | E10: Yes | F10: Picking | H10: =IFERROR(VLOOKUP($A10,'Crew Sheet'!#REF!,2,FALSE),"") | I10: =IF($T10<>"x","", IF(TRIM($D10)="P","Picking", IF(AND(COUNTIF($F10,"*Unload*"),COUNTIF($D10,"*U*")),"Unloading", IF(AND(COUNTIF($D10,"*L*"),COUNTIFS($I$1:I9,"Loading",$T$1:T9,"x")<ROUNDUP(_xlfn.XLOOKUP("Loaders",'Crew Sheet'!$H:$H,'Crew Sheet'!$L:$L),0)),"Loading", IF(AND(COUNTIF($D10,"*R*"),COUNTIFS($I$1:I9,"Receiving",$T$1:T9,"x")<ROUNDUP(SUM('Crew Sheet'!$L$10:$L$11),0)),"Receiving", IF(AND(COUNTIF($F10,"*Pick*"),COUNTIF($D10,"*P*")),"Picking", IF(AND(COUNTIF($F10,"*Task*"),COUNTIF($D10,"*T*")),"Replen/Pallets/Putaways", IF(COUNTIF($D10,"*T*"),"Replen/Pallets/Putaways","Lead/Extra")))))))) | N10: Unloading | O10: U | T10: =IFERROR(VLOOKUP($A10,'Crew Sheet'!$A:$C,2,FALSE),"") -> 1 | U10: =IF($T10<>"x",-999,IF(IFERROR(ISNUMBER(SEARCH("P",$D10)),FALSE),100,0)+IF(IFERROR(ISNUMBER(SEARCH("Pick",$F10)),FALSE),1000,0)+IF($G10="Above Average",100,IF($G10="Average",50,0))) -> -999 | V10: =IF($T10<>"x",-999,IF(IFERROR(ISNUMBER(SEARCH("L",$D10)),FALSE),100,0)+IF(IFERROR(ISNUMBER(SEARCH("Load",$F10)),FALSE),1000,0)+IF($G10="Above Average",100,IF($G10="Average",50,0))) -> -999 | W10: =IF($T10<>"x",-999,IF(IFERROR(ISNUMBER(SEARCH("T",$D10)),FALSE),100,0)+IF(OR(IFERROR(ISNUMBER(SEARCH("Task",$F10)),FALSE),IFERROR(ISNUMBER(SEARCH("Putaway",$F10)),FALSE),IFERROR(ISNUMBER(SEARCH("Replen",$F10)),FALSE),IFERROR(ISNUMBER(SEARCH("Full Pallet",$F10)),FALSE)),1000,0)+IF($G10="Above Average",100,IF($G10="Average",50,0))) -> -999 | X10: =IF($T10<>"x",-999,IF(IFERROR(ISNUMBER(SEARCH("U",$D10)),FALSE),100,0)+IF(IFERROR(ISNUMBER(SEARCH("Unload",$F10)),FALSE),1000,0)+IF($G10="Above Average",100,IF($G10="Average",50,0))) -> -999 | Y10: =IF($T10<>"x",-999,IF(IFERROR(ISNUMBER(SEARCH("R",$D10)),FALSE),100,0)+IF(IFERROR(ISNUMBER(SEARCH("Receiv",$F10)),FALSE),1000,0)+IF($G10="Above Average",100,IF($G10="Average",50,0))) -> -999
A11: Felipe P. | B11: 1st | C11: Weekend | D11: P | E11: Yes | F11: Picking | H11: =IFERROR(VLOOKUP($A11,'Crew Sheet'!#REF!,2,FALSE),"") | I11: =IF($T11<>"x","", IF(TRIM($D11)="P","Picking", IF(AND(COUNTIF($F11,"*Unload*"),COUNTIF($D11,"*U*")),"Unloading", IF(AND(COUNTIF($D11,"*L*"),COUNTIFS($I$1:I10,"Loading",$T$1:T10,"x")<ROUNDUP(_xlfn.XLOOKUP("Loaders",'Crew Sheet'!$H:$H,'Crew Sheet'!$L:$L),0)),"Loading", IF(AND(COUNTIF($D11,"*R*"),COUNTIFS($I$1:I10,"Receiving",$T$1:T10,"x")<ROUNDUP(SUM('Crew Sheet'!$L$10:$L$11),0)),"Receiving", IF(AND(COUNTIF($F11,"*Pick*"),COUNTIF($D11,"*P*")),"Picking", IF(AND(COUNTIF($F11,"*Task*"),COUNTIF($D11,"*T*")),"Replen/Pallets/Putaways", IF(COUNTIF($D11,"*T*"),"Replen/Pallets/Putaways","Lead/Extra")))))))) | N11: Loading | O11: L | T11: =IFERROR(VLOOKUP($A11,'Crew Sheet'!$A:$C,2,FALSE),"") -> 1 | U11: =IF($T11<>"x",-999,IF(IFERROR(ISNUMBER(SEARCH("P",$D11)),FALSE),100,0)+IF(IFERROR(ISNUMBER(SEARCH("Pick",$F11)),FALSE),1000,0)+IF($G11="Above Average",100,IF($G11="Average",50,0))) -> -999 | V11: =IF($T11<>"x",-999,IF(IFERROR(ISNUMBER(SEARCH("L",$D11)),FALSE),100,0)+IF(IFERROR(ISNUMBER(SEARCH("Load",$F11)),FALSE),1000,0)+IF($G11="Above Average",100,IF($G11="Average",50,0))) -> -999 | W11: =IF($T11<>"x",-999,IF(IFERROR(ISNUMBER(SEARCH("T",$D11)),FALSE),100,0)+IF(OR(IFERROR(ISNUMBER(SEARCH("Task",$F11)),FALSE),IFERROR(ISNUMBER(SEARCH("Putaway",$F11)),FALSE),IFERROR(ISNUMBER(SEARCH("Replen",$F11)),FALSE),IFERROR(ISNUMBER(SEARCH("Full Pallet",$F11)),FALSE)),1000,0)+IF($G11="Above Average",100,IF($G11="Average",50,0))) -> -999 | X11: =IF($T11<>"x",-999,IF(IFERROR(ISNUMBER(SEARCH("U",$D11)),FALSE),100,0)+IF(IFERROR(ISNUMBER(SEARCH("Unload",$F11)),FALSE),1000,0)+IF($G11="Above Average",100,IF($G11="Average",50,0))) -> -999 | Y11: =IF($T11<>"x",-999,IF(IFERROR(ISNUMBER(SEARCH("R",$D11)),FALSE),100,0)+IF(IFERROR(ISNUMBER(SEARCH("Receiv",$F11)),FALSE),1000,0)+IF($G11="Above Average",100,IF($G11="Average",50,0))) -> -999
A12: Francisco N. | B12: 1st | C12: Weekend | D12: P | E12: No | F12: Picking | H12: =IFERROR(VLOOKUP($A12,'Crew Sheet'!#REF!,2,FALSE),"") | I12: =IF($T12<>"x","", IF(TRIM($D12)="P","Picking", IF(AND(COUNTIF($F12,"*Unload*"),COUNTIF($D12,"*U*")),"Unloading", IF(AND(COUNTIF($D12,"*L*"),COUNTIFS($I$1:I11,"Loading",$T$1:T11,"x")<ROUNDUP(_xlfn.XLOOKUP("Loaders",'Crew Sheet'!$H:$H,'Crew Sheet'!$L:$L),0)),"Loading", IF(AND(COUNTIF($D12,"*R*"),COUNTIFS($I$1:I11,"Receiving",$T$1:T11,"x")<ROUNDUP(SUM('Crew Sheet'!$L$10:$L$11),0)),"Receiving", IF(AND(COUNTIF($F12,"*Pick*"),COUNTIF($D12,"*P*")),"Picking", IF(AND(COUNTIF($F12,"*Task*"),COUNTIF($D12,"*T*")),"Replen/Pallets/Putaways", IF(COUNTIF($D12,"*T*"),"Replen/Pallets/Putaways","Lead/Extra")))))))) | N12: Replenishments | O12: T | T12: =IFERROR(VLOOKUP($A12,'Crew Sheet'!$A:$C,2,FALSE),"") -> 1 | U12: =IF($T12<>"x",-999,IF(IFERROR(ISNUMBER(SEARCH("P",$D12)),FALSE),100,0)+IF(IFERROR(ISNUMBER(SEARCH("Pick",$F12)),FALSE),1000,0)+IF($G12="Above Average",100,IF($G12="Average",50,0))) -> -999 | V12: =IF($T12<>"x",-999,IF(IFERROR(ISNUMBER(SEARCH("L",$D12)),FALSE),100,0)+IF(IFERROR(ISNUMBER(SEARCH("Load",$F12)),FALSE),1000,0)+IF($G12="Above Average",100,IF($G12="Average",50,0))) -> -999 | W12: =IF($T12<>"x",-999,IF(IFERROR(ISNUMBER(SEARCH("T",$D12)),FALSE),100,0)+IF(OR(IFERROR(ISNUMBER(SEARCH("Task",$F12)),FALSE),IFERROR(ISNUMBER(SEARCH("Putaway",$F12)),FALSE),IFERROR(ISNUMBER(SEARCH("Replen",$F12)),FALSE),IFERROR(ISNUMBER(SEARCH("Full Pallet",$F12)),FALSE)),1000,0)+IF($G12="Above Average",100,IF($G12="Average",50,0))) -> -999 | X12: =IF($T12<>"x",-999,IF(IFERROR(ISNUMBER(SEARCH("U",$D12)),FALSE),100,0)+IF(IFERROR(ISNUMBER(SEARCH("Unload",$F12)),FALSE),1000,0)+IF($G12="Above Average",100,IF($G12="Average",50,0))) -> -999 | Y12: =IF($T12<>"x",-999,IF(IFERROR(ISNUMBER(SEARCH("R",$D12)),FALSE),100,0)+IF(IFERROR(ISNUMBER(SEARCH("Receiv",$F12)),FALSE),1000,0)+IF($G12="Above Average",100,IF($G12="Average",50,0))) -> -999
A13: Henry | B13: 1st | C13: Weekday | D13: P | E13: Yes | F13: Picking | H13: =IFERROR(VLOOKUP($A13,'Crew Sheet'!#REF!,2,FALSE),"") | I13: =IF($T13<>"x","", IF(TRIM($D13)="P","Picking", IF(AND(COUNTIF($F13,"*Unload*"),COUNTIF($D13,"*U*")),"Unloading", IF(AND(COUNTIF($D13,"*L*"),COUNTIFS($I$1:I12,"Loading",$T$1:T12,"x")<ROUNDUP(_xlfn.XLOOKUP("Loaders",'Crew Sheet'!$H:$H,'Crew Sheet'!$L:$L),0)),"Loading", IF(AND(COUNTIF($D13,"*R*"),COUNTIFS($I$1:I12,"Receiving",$T$1:T12,"x")<ROUNDUP(SUM('Crew Sheet'!$L$10:$L$11),0)),"Receiving", IF(AND(COUNTIF($F13,"*Pick*"),COUNTIF($D13,"*P*")),"Picking", IF(AND(COUNTIF($F13,"*Task*"),COUNTIF($D13,"*T*")),"Replen/Pallets/Putaways", IF(COUNTIF($D13,"*T*"),"Replen/Pallets/Putaways","Lead/Extra")))))))) | N13: Pallet Pulls | T13: =IFERROR(VLOOKUP($A13,'Crew Sheet'!$A:$C,2,FALSE),"") -> 1 | U13: =IF($T13<>"x",-999,IF(IFERROR(ISNUMBER(SEARCH("P",$D13)),FALSE),100,0)+IF(IFERROR(ISNUMBER(SEARCH("Pick",$F13)),FALSE),1000,0)+IF($G13="Above Average",100,IF($G13="Average",50,0))) -> -999 | V13: =IF($T13<>"x",-999,IF(IFERROR(ISNUMBER(SEARCH("L",$D13)),FALSE),100,0)+IF(IFERROR(ISNUMBER(SEARCH("Load",$F13)),FALSE),1000,0)+IF($G13="Above Average",100,IF($G13="Average",50,0))) -> -999 | W13: =IF($T13<>"x",-999,IF(IFERROR(ISNUMBER(SEARCH("T",$D13)),FALSE),100,0)+IF(OR(IFERROR(ISNUMBER(SEARCH("Task",$F13)),FALSE),IFERROR(ISNUMBER(SEARCH("Putaway",$F13)),FALSE),IFERROR(ISNUMBER(SEARCH("Replen",$F13)),FALSE),IFERROR(ISNUMBER(SEARCH("Full Pallet",$F13)),FALSE)),1000,0)+IF($G13="Above Average",100,IF($G13="Average",50,0))) -> -999 | X13: =IF($T13<>"x",-999,IF(IFERROR(ISNUMBER(SEARCH("U",$D13)),FALSE),100,0)+IF(IFERROR(ISNUMBER(SEARCH("Unload",$F13)),FALSE),1000,0)+IF($G13="Above Average",100,IF($G13="Average",50,0))) -> -999 | Y13: =IF($T13<>"x",-999,IF(IFERROR(ISNUMBER(SEARCH("R",$D13)),FALSE),100,0)+IF(IFERROR(ISNUMBER(SEARCH("Receiv",$F13)),FALSE),1000,0)+IF($G13="Above Average",100,IF($G13="Average",50,0))) -> -999
A14: Jeremiah A. | B14: 1st | C14: Weekday | D14: P | E14: No | F14: Picking | H14: =IFERROR(VLOOKUP($A14,'Crew Sheet'!#REF!,2,FALSE),"") | I14: =IF($T14<>"x","", IF(TRIM($D14)="P","Picking", IF(AND(COUNTIF($F14,"*Unload*"),COUNTIF($D14,"*U*")),"Unloading", IF(AND(COUNTIF($D14,"*L*"),COUNTIFS($I$1:I13,"Loading",$T$1:T13,"x")<ROUNDUP(_xlfn.XLOOKUP("Loaders",'Crew Sheet'!$H:$H,'Crew Sheet'!$L:$L),0)),"Loading", IF(AND(COUNTIF($D14,"*R*"),COUNTIFS($I$1:I13,"Receiving",$T$1:T13,"x")<ROUNDUP(SUM('Crew Sheet'!$L$10:$L$11),0)),"Receiving", IF(AND(COUNTIF($F14,"*Pick*"),COUNTIF($D14,"*P*")),"Picking", IF(AND(COUNTIF($F14,"*Task*"),COUNTIF($D14,"*T*")),"Replen/Pallets/Putaways", IF(COUNTIF($D14,"*T*"),"Replen/Pallets/Putaways","Lead/Extra")))))))) | N14: Putaways | T14: =IFERROR(VLOOKUP($A14,'Crew Sheet'!$A:$C,2,FALSE),"") -> 1 | U14: =IF($T14<>"x",-999,IF(IFERROR(ISNUMBER(SEARCH("P",$D14)),FALSE),100,0)+IF(IFERROR(ISNUMBER(SEARCH("Pick",$F14)),FALSE),1000,0)+IF($G14="Above Average",100,IF($G14="Average",50,0))) -> -999 | V14: =IF($T14<>"x",-999,IF(IFERROR(ISNUMBER(SEARCH("L",$D14)),FALSE),100,0)+IF(IFERROR(ISNUMBER(SEARCH("Load",$F14)),FALSE),1000,0)+IF($G14="Above Average",100,IF($G14="Average",50,0))) -> -999 | W14: =IF($T14<>"x",-999,IF(IFERROR(ISNUMBER(SEARCH("T",$D14)),FALSE),100,0)+IF(OR(IFERROR(ISNUMBER(SEARCH("Task",$F14)),FALSE),IFERROR(ISNUMBER(SEARCH("Putaway",$F14)),FALSE),IFERROR(ISNUMBER(SEARCH("Replen",$F14)),FALSE),IFERROR(ISNUMBER(SEARCH("Full Pallet",$F14)),FALSE)),1000,0)+IF($G14="Above Average",100,IF($G14="Average",50,0))) -> -999 | X14: =IF($T14<>"x",-999,IF(IFERROR(ISNUMBER(SEARCH("U",$D14)),FALSE),100,0)+IF(IFERROR(ISNUMBER(SEARCH("Unload",$F14)),FALSE),1000,0)+IF($G14="Above Average",100,IF($G14="Average",50,0))) -> -999 | Y14: =IF($T14<>"x",-999,IF(IFERROR(ISNUMBER(SEARCH("R",$D14)),FALSE),100,0)+IF(IFERROR(ISNUMBER(SEARCH("Receiv",$F14)),FALSE),1000,0)+IF($G14="Above Average",100,IF($G14="Average",50,0))) -> -999
A15: Jose R. | B15: 1st | C15: Weekend | D15: P | E15: No | F15: Picking | H15: =IFERROR(VLOOKUP($A15,'Crew Sheet'!#REF!,2,FALSE),"") | I15: =IF($T15<>"x","", IF(TRIM($D15)="P","Picking", IF(AND(COUNTIF($F15,"*Unload*"),COUNTIF($D15,"*U*")),"Unloading", IF(AND(COUNTIF($D15,"*L*"),COUNTIFS($I$1:I14,"Loading",$T$1:T14,"x")<ROUNDUP(_xlfn.XLOOKUP("Loaders",'Crew Sheet'!$H:$H,'Crew Sheet'!$L:$L),0)),"Loading", IF(AND(COUNTIF($D15,"*R*"),COUNTIFS($I$1:I14,"Receiving",$T$1:T14,"x")<ROUNDUP(SUM('Crew Sheet'!$L$10:$L$11),0)),"Receiving", IF(AND(COUNTIF($F15,"*Pick*"),COUNTIF($D15,"*P*")),"Picking", IF(AND(COUNTIF($F15,"*Task*"),COUNTIF($D15,"*T*")),"Replen/Pallets/Putaways", IF(COUNTIF($D15,"*T*"),"Replen/Pallets/Putaways","Lead/Extra")))))))) | T15: =IFERROR(VLOOKUP($A15,'Crew Sheet'!$A:$C,2,FALSE),"") | U15: =IF($T15<>"x",-999,IF(IFERROR(ISNUMBER(SEARCH("P",$D15)),FALSE),100,0)+IF(IFERROR(ISNUMBER(SEARCH("Pick",$F15)),FALSE),1000,0)+IF($G15="Above Average",100,IF($G15="Average",50,0))) -> -999 | V15: =IF($T15<>"x",-999,IF(IFERROR(ISNUMBER(SEARCH("L",$D15)),FALSE),100,0)+IF(IFERROR(ISNUMBER(SEARCH("Load",$F15)),FALSE),1000,0)+IF($G15="Above Average",100,IF($G15="Average",50,0))) -> -999 | W15: =IF($T15<>"x",-999,IF(IFERROR(ISNUMBER(SEARCH("T",$D15)),FALSE),100,0)+IF(OR(IFERROR(ISNUMBER(SEARCH("Task",$F15)),FALSE),IFERROR(ISNUMBER(SEARCH("Putaway",$F15)),FALSE),IFERROR(ISNUMBER(SEARCH("Replen",$F15)),FALSE),IFERROR(ISNUMBER(SEARCH("Full Pallet",$F15)),FALSE)),1000,0)+IF($G15="Above Average",100,IF($G15="Average",50,0))) -> -999 | X15: =IF($T15<>"x",-999,IF(IFERROR(ISNUMBER(SEARCH("U",$D15)),FALSE),100,0)+IF(IFERROR(ISNUMBER(SEARCH("Unload",$F15)),FALSE),1000,0)+IF($G15="Above Average",100,IF($G15="Average",50,0))) -> -999 | Y15: =IF($T15<>"x",-999,IF(IFERROR(ISNUMBER(SEARCH("R",$D15)),FALSE),100,0)+IF(IFERROR(ISNUMBER(SEARCH("Receiv",$F15)),FALSE),1000,0)+IF($G15="Above Average",100,IF($G15="Average",50,0))) -> -999
A16: Michael O. | B16: 1st | C16: Weekend | D16: P | E16: Yes | F16: Picking | H16: =IFERROR(VLOOKUP($A16,'Crew Sheet'!#REF!,2,FALSE),"") | I16: =IF($T16<>"x","", IF(TRIM($D16)="P","Picking", IF(AND(COUNTIF($F16,"*Unload*"),COUNTIF($D16,"*U*")),"Unloading", IF(AND(COUNTIF($D16,"*L*"),COUNTIFS($I$1:I15,"Loading",$T$1:T15,"x")<ROUNDUP(_xlfn.XLOOKUP("Loaders",'Crew Sheet'!$H:$H,'Crew Sheet'!$L:$L),0)),"Loading", IF(AND(COUNTIF($D16,"*R*"),COUNTIFS($I$1:I15,"Receiving",$T$1:T15,"x")<ROUNDUP(SUM('Crew Sheet'!$L$10:$L$11),0)),"Receiving", IF(AND(COUNTIF($F16,"*Pick*"),COUNTIF($D16,"*P*")),"Picking", IF(AND(COUNTIF($F16,"*Task*"),COUNTIF($D16,"*T*")),"Replen/Pallets/Putaways", IF(COUNTIF($D16,"*T*"),"Replen/Pallets/Putaways","Lead/Extra")))))))) | T16: =IFERROR(VLOOKUP($A16,'Crew Sheet'!$A:$C,2,FALSE),"") -> 1 | U16: =IF($T16<>"x",-999,IF(IFERROR(ISNUMBER(SEARCH("P",$D16)),FALSE),100,0)+IF(IFERROR(ISNUMBER(SEARCH("Pick",$F16)),FALSE),1000,0)+IF($G16="Above Average",100,IF($G16="Average",50,0))) -> -999 | V16: =IF($T16<>"x",-999,IF(IFERROR(ISNUMBER(SEARCH("L",$D16)),FALSE),100,0)+IF(IFERROR(ISNUMBER(SEARCH("Load",$F16)),FALSE),1000,0)+IF($G16="Above Average",100,IF($G16="Average",50,0))) -> -999 | W16: =IF($T16<>"x",-999,IF(IFERROR(ISNUMBER(SEARCH("T",$D16)),FALSE),100,0)+IF(OR(IFERROR(ISNUMBER(SEARCH("Task",$F16)),FALSE),IFERROR(ISNUMBER(SEARCH("Putaway",$F16)),FALSE),IFERROR(ISNUMBER(SEARCH("Replen",$F16)),FALSE),IFERROR(ISNUMBER(SEARCH("Full Pallet",$F16)),FALSE)),1000,0)+IF($G16="Above Average",100,IF($G16="Average",50,0))) -> -999 | X16: =IF($T16<>"x",-999,IF(IFERROR(ISNUMBER(SEARCH("U",$D16)),FALSE),100,0)+IF(IFERROR(ISNUMBER(SEARCH("Unload",$F16)),FALSE),1000,0)+IF($G16="Above Average",100,IF($G16="Average",50,0))) -> -999 | Y16: =IF($T16<>"x",-999,IF(IFERROR(ISNUMBER(SEARCH("R",$D16)),FALSE),100,0)+IF(IFERROR(ISNUMBER(SEARCH("Receiv",$F16)),FALSE),1000,0)+IF($G16="Above Average",100,IF($G16="Average",50,0))) -> -999
A17: Oscar A | B17: 1st | C17: Weekend | D17: P | E17: No | F17: Picking | H17: =IFERROR(VLOOKUP($A17,'Crew Sheet'!#REF!,2,FALSE),"") | I17: =IF($T17<>"x","", IF(TRIM($D17)="P","Picking", IF(AND(COUNTIF($F17,"*Unload*"),COUNTIF($D17,"*U*")),"Unloading", IF(AND(COUNTIF($D17,"*L*"),COUNTIFS($I$1:I16,"Loading",$T$1:T16,"x")<ROUNDUP(_xlfn.XLOOKUP("Loaders",'Crew Sheet'!$H:$H,'Crew Sheet'!$L:$L),0)),"Loading", IF(AND(COUNTIF($D17,"*R*"),COUNTIFS($I$1:I16,"Receiving",$T$1:T16,"x")<ROUNDUP(SUM('Crew Sheet'!$L$10:$L$11),0)),"Receiving", IF(AND(COUNTIF($F17,"*Pick*"),COUNTIF($D17,"*P*")),"Picking", IF(AND(COUNTIF($F17,"*Task*"),COUNTIF($D17,"*T*")),"Replen/Pallets/Putaways", IF(COUNTIF($D17,"*T*"),"Replen/Pallets/Putaways","Lead/Extra")))))))) | T17: =IFERROR(VLOOKUP($A17,'Crew Sheet'!$A:$C,2,FALSE),"") -> 1 | U17: =IF($T17<>"x",-999,IF(IFERROR(ISNUMBER(SEARCH("P",$D17)),FALSE),100,0)+IF(IFERROR(ISNUMBER(SEARCH("Pick",$F17)),FALSE),1000,0)+IF($G17="Above Average",100,IF($G17="Average",50,0))) -> -999 | V17: =IF($T17<>"x",-999,IF(IFERROR(ISNUMBER(SEARCH("L",$D17)),FALSE),100,0)+IF(IFERROR(ISNUMBER(SEARCH("Load",$F17)),FALSE),1000,0)+IF($G17="Above Average",100,IF($G17="Average",50,0))) -> -999 | W17: =IF($T17<>"x",-999,IF(IFERROR(ISNUMBER(SEARCH("T",$D17)),FALSE),100,0)+IF(OR(IFERROR(ISNUMBER(SEARCH("Task",$F17)),FALSE),IFERROR(ISNUMBER(SEARCH("Putaway",$F17)),FALSE),IFERROR(ISNUMBER(SEARCH("Replen",$F17)),FALSE),IFERROR(ISNUMBER(SEARCH("Full Pallet",$F17)),FALSE)),1000,0)+IF($G17="Above Average",100,IF($G17="Average",50,0))) -> -999 | X17: =IF($T17<>"x",-999,IF(IFERROR(ISNUMBER(SEARCH("U",$D17)),FALSE),100,0)+IF(IFERROR(ISNUMBER(SEARCH("Unload",$F17)),FALSE),1000,0)+IF($G17="Above Average",100,IF($G17="Average",50,0))) -> -999 | Y17: =IF($T17<>"x",-999,IF(IFERROR(ISNUMBER(SEARCH("R",$D17)),FALSE),100,0)+IF(IFERROR(ISNUMBER(SEARCH("Receiv",$F17)),FALSE),1000,0)+IF($G17="Above Average",100,IF($G17="Average",50,0))) -> -999
A18: Oscar B. | B18: 1st | C18: Weekday | D18: P/T | E18: No | F18: Picking | H18: =IFERROR(VLOOKUP($A18,'Crew Sheet'!#REF!,2,FALSE),"") | I18: =IF($T18<>"x","", IF(TRIM($D18)="P","Picking", IF(AND(COUNTIF($F18,"*Unload*"),COUNTIF($D18,"*U*")),"Unloading", IF(AND(COUNTIF($D18,"*L*"),COUNTIFS($I$1:I17,"Loading",$T$1:T17,"x")<ROUNDUP(_xlfn.XLOOKUP("Loaders",'Crew Sheet'!$H:$H,'Crew Sheet'!$L:$L),0)),"Loading", IF(AND(COUNTIF($D18,"*R*"),COUNTIFS($I$1:I17,"Receiving",$T$1:T17,"x")<ROUNDUP(SUM('Crew Sheet'!$L$10:$L$11),0)),"Receiving", IF(AND(COUNTIF($F18,"*Pick*"),COUNTIF($D18,"*P*")),"Picking", IF(AND(COUNTIF($F18,"*Task*"),COUNTIF($D18,"*T*")),"Replen/Pallets/Putaways", IF(COUNTIF($D18,"*T*"),"Replen/Pallets/Putaways","Lead/Extra")))))))) | T18: =IFERROR(VLOOKUP($A18,'Crew Sheet'!$A:$C,2,FALSE),"") -> 1 | U18: =IF($T18<>"x",-999,IF(IFERROR(ISNUMBER(SEARCH("P",$D18)),FALSE),100,0)+IF(IFERROR(ISNUMBER(SEARCH("Pick",$F18)),FALSE),1000,0)+IF($G18="Above Average",100,IF($G18="Average",50,0))) -> -999 | V18: =IF($T18<>"x",-999,IF(IFERROR(ISNUMBER(SEARCH("L",$D18)),FALSE),100,0)+IF(IFERROR(ISNUMBER(SEARCH("Load",$F18)),FALSE),1000,0)+IF($G18="Above Average",100,IF($G18="Average",50,0))) -> -999 | W18: =IF($T18<>"x",-999,IF(IFERROR(ISNUMBER(SEARCH("T",$D18)),FALSE),100,0)+IF(OR(IFERROR(ISNUMBER(SEARCH("Task",$F18)),FALSE),IFERROR(ISNUMBER(SEARCH("Putaway",$F18)),FALSE),IFERROR(ISNUMBER(SEARCH("Replen",$F18)),FALSE),IFERROR(ISNUMBER(SEARCH("Full Pallet",$F18)),FALSE)),1000,0)+IF($G18="Above Average",100,IF($G18="Average",50,0))) -> -999 | X18: =IF($T18<>"x",-999,IF(IFERROR(ISNUMBER(SEARCH("U",$D18)),FALSE),100,0)+IF(IFERROR(ISNUMBER(SEARCH("Unload",$F18)),FALSE),1000,0)+IF($G18="Above Average",100,IF($G18="Average",50,0))) -> -999 | Y18: =IF($T18<>"x",-999,IF(IFERROR(ISNUMBER(SEARCH("R",$D18)),FALSE),100,0)+IF(IFERROR(ISNUMBER(SEARCH("Receiv",$F18)),FALSE),1000,0)+IF($G18="Above Average",100,IF($G18="Average",50,0))) -> -999
A19: Robert R. | B19: 1st | C19: Weekend | D19: P | E19: Yes | F19: Picking | H19: =IFERROR(VLOOKUP($A19,'Crew Sheet'!#REF!,2,FALSE),"") | I19: =IF($T19<>"x","", IF(TRIM($D19)="P","Picking", IF(AND(COUNTIF($F19,"*Unload*"),COUNTIF($D19,"*U*")),"Unloading", IF(AND(COUNTIF($D19,"*L*"),COUNTIFS($I$1:I18,"Loading",$T$1:T18,"x")<ROUNDUP(_xlfn.XLOOKUP("Loaders",'Crew Sheet'!$H:$H,'Crew Sheet'!$L:$L),0)),"Loading", IF(AND(COUNTIF($D19,"*R*"),COUNTIFS($I$1:I18,"Receiving",$T$1:T18,"x")<ROUNDUP(SUM('Crew Sheet'!$L$10:$L$11),0)),"Receiving", IF(AND(COUNTIF($F19,"*Pick*"),COUNTIF($D19,"*P*")),"Picking", IF(AND(COUNTIF($F19,"*Task*"),COUNTIF($D19,"*T*")),"Replen/Pallets/Putaways", IF(COUNTIF($D19,"*T*"),"Replen/Pallets/Putaways","Lead/Extra")))))))) | T19: =IFERROR(VLOOKUP($A19,'Crew Sheet'!$A:$C,2,FALSE),"") -> 1 | U19: =IF($T19<>"x",-999,IF(IFERROR(ISNUMBER(SEARCH("P",$D19)),FALSE),100,0)+IF(IFERROR(ISNUMBER(SEARCH("Pick",$F19)),FALSE),1000,0)+IF($G19="Above Average",100,IF($G19="Average",50,0))) -> -999 | V19: =IF($T19<>"x",-999,IF(IFERROR(ISNUMBER(SEARCH("L",$D19)),FALSE),100,0)+IF(IFERROR(ISNUMBER(SEARCH("Load",$F19)),FALSE),1000,0)+IF($G19="Above Average",100,IF($G19="Average",50,0))) -> -999 | W19: =IF($T19<>"x",-999,IF(IFERROR(ISNUMBER(SEARCH("T",$D19)),FALSE),100,0)+IF(OR(IFERROR(ISNUMBER(SEARCH("Task",$F19)),FALSE),IFERROR(ISNUMBER(SEARCH("Putaway",$F19)),FALSE),IFERROR(ISNUMBER(SEARCH("Replen",$F19)),FALSE),IFERROR(ISNUMBER(SEARCH("Full Pallet",$F19)),FALSE)),1000,0)+IF($G19="Above Average",100,IF($G19="Average",50,0))) -> -999 | X19: =IF($T19<>"x",-999,IF(IFERROR(ISNUMBER(SEARCH("U",$D19)),FALSE),100,0)+IF(IFERROR(ISNUMBER(SEARCH("Unload",$F19)),FALSE),1000,0)+IF($G19="Above Average",100,IF($G19="Average",50,0))) -> -999 | Y19: =IF($T19<>"x",-999,IF(IFERROR(ISNUMBER(SEARCH("R",$D19)),FALSE),100,0)+IF(IFERROR(ISNUMBER(SEARCH("Receiv",$F19)),FALSE),1000,0)+IF($G19="Above Average",100,IF($G19="Average",50,0))) -> -999
